Workbook

Sheet Thesis

Sheet Reporting

Sheet IS
A2: Consolidated Statements of Operations (in $ thousands)
A4: Line Item | B4: 2023A | C4: 2024A | D4: 2025A
A5: Transaction revenue:
A6: Transaction revenue - consumer, net | B6: 1334000 | C6: 3430000 | D6: 3320000
A7: Transaction revenue - institutional, net | B7: 90000 | C7: 346000 | D7: 480000
A8: Transaction revenue - other, net | B8: 96000 | C8: 210000 | D8: 253000
A9: Total transaction revenue | B9: =SUM(B6:B8) -> 1520000 | C9: =SUM(C6:C8) -> 3986000 | D9: =SUM(D6:D8) -> 4053000
A11: Subscription and services revenue:
A12: Stablecoin revenue | B12: 694000 | C12: 910000 | D12: 1400000
A13: Blockchain rewards revenue | B13: 331000 | C13: 706000 | D13: 723000
A14: Interest and finance revenue | B14: 187000 | C14: 266000 | D14: 380000
A15: Custodial and other | B15: 196000 | C15: 425000 | D15: 327000
A16: Total subscription and services revenue | B16: =SUM(B12:B15) -> 1408000 | C16: =SUM(C12:C15) -> 2307000 | D16: =SUM(D12:D15) -> 2830000
A18: Total other revenue | B18: =181000 -> 181000 | C18: 271000 | D18: 298000
A20: Total net revenue | B20: =B16+B9+B18 -> 3109000 | C20: =C16+C9+C18 -> 6564000 | D20: =D16+D9+D18 -> 7181000
A22: Operating Expenses
A23: Transaction expenses | B23: 421000 | C23: 898000 | D23: 1050000
A24: Technology and development | B24: 1325000 | C24: 1468000 | D24: 1680000
A25: Sales and marketing | B25: 332000 | C25: 654000 | D25: 850000
A26: General and administrative | B26: 1074000 | C26: 1300000 | D26: 1450000
A27: Losses (gains) on crypto assets held for operations, net | C27: -72000 | D27: -95000
A28: Other operating expense, net | B28: 10000 | C28: 8000 | D28: 810000
A29: Crypto asset impairment, net | B29: -35000
A30: Restructuring | B30: 142000
A31: Total operating expenses | B31: =SUM(B23:B30) -> 3269000 | C31: =SUM(C23:C30) -> 4256000 | D31: =SUM(D23:D30) -> 5745000
D32: =(D31-C31)/C31 -> 0.34985902
A33: Income from operations | B33: =B20-B31 -> -160000 | C33: =C20-C31 -> 2308000 | D33: =D20-D31 -> 1436000
A34: Interest expense | B34: 83000 | C34: 81000 | D34: 85000
A35: Gains on crypto assets held for investment, net | C35: -687000 | D35: 530000
A36: Other income (expense), net | B36: -167000 | C36: -29000 | D36: -700000
A37: Income before taxes | B37: =B33-SUM(B34:B36) -> -76000 | C37: =C33-SUM(C34:C36) -> 2943000 | D37: =D33-SUM(D34:D36) -> 1521000
A38: Provision for income taxes | B38: -172000 | C38: 364000 | D38: 262000
A39: Net income | B39: =B37-B38 -> 96000 | C39: =C37-C38 -> 2579000 | D39: =D37-D38 -> 1259000
A41: Taxes marginal rate | C41: =C38/C37 -> 0.12368332 | D41: =D38/D33 -> 0.18245125

Sheet BS
A2: Consolidated Balance Sheets (in $ thousands)
A4: Line Item | B4: Dec 31, 2024 | C4: Dec 31, 2025
A5: ASSETS
A7: Current assets:
A8: Cash and cash equivalents | B8: 9310000 | C8: 11290000
A9: Restricted cash and cash equivalents | B9: 350000 | C9: 330000
A10: Customer custodial funds | B10: 6160000 | C10: 5350000
A11: Crypto assets held for operations | B11: 80000 | C11: 120000
A12: Loan receivables | B12: 640000 | C12: 1350000
A13: Crypto assets held as collateral | B13: 770000 | C13: 820000
A14: Crypto assets borrowed | B14: 260000 | C14: 320000
A15: Accounts receivable, net | B15: 270000 | C15: 310000
A16: Marketable investments | B16: 0 | C16: 310000
A17: Other current assets | B17: 280000 | C17: 190000
A18: Total current assets | B18: =SUM(B8:B17) -> 18120000 | C18: =SUM(C8:C17) -> 20390000
A20: Non-current assets:
A21: Crypto assets held for investment | B21: 1550000 | C21: 2000000
A22: Strategic investments | B22: 370000 | C22: 620000
A23: Deferred tax assets | B23: 940000 | C23: 570000
A24: Software and equipment, net | B24: 200000 | C24: 270000
A25: Goodwill | B25: 1140000 | C25: 4170000
A26: Intangible assets, net | B26: 50000 | C26: 1400000
A27: Other non-current assets | B27: 170000 | C27: 260000
A28: Total non-current assets | B28: =SUM(B21:B27) -> 4420000 | C28: =SUM(C21:C27) -> 9290000
A30: TOTAL ASSETS | B30: 22540000 | C30: =C28+C18 -> 29680000
A32: LIABILITIES & EQUITY
A34: Current liabilities:
A35: Customer custodial fund liabilities | B35: 6160000 | C35: 5350000
A36: Accounts payable | B36: 60000 | C36: 120000
A37: Current portion of long-term debt | B37: 0 | C37: 1270000
A38: Short-term borrowings | B38: 380000 | C38: 450000
A39: Obligation to return collateral | B39: 790000 | C39: 830000
A40: Accrued expenses and other current liabilities | B40: 550000 | C40: 690000
A41: Total current liabilities | B41: =SUM(B35:B40) -> 7940000 | C41: =SUM(C35:C40) -> 8710000
A43: Non-current liabilities
A44: Long-term debt | B44: 4230000 | C44: 5940000
A45: Other non-current liabilities | B45: 90000 | C45: 240000
A46: Total non-current liabilities | B46: =SUM(B44:B45) -> 4320000 | C46: =SUM(C44:C45) -> 6180000
A48: TOTAL LIABILITIES | B48: =B46+B41 -> 12260000 | C48: =C46+C41 -> 14890000
A50: Stockholders' Equity:
...

Sheet CF
A2: Consolidated Statements of Cash Flows (in $ thousands)
A4: Line Item | B4: 2023A | C4: 2024A | D4: 2025A
A5: OPERATING ACTIVITIES
A6: Net income | B6: 95000 | C6: 2579000 | D6: 1260000
A7: Depreciation and amortization | B7: 140000 | C7: 128000 | D7: 189000
A8: Stock-based compensation | B8: 781000 | C8: 913000 | D8: 840000
A9: Deferred taxes | B9: -216000 | C9: 151000 | D9: 238000
A10: (Gains) losses on investment | B10: -24000 | C10: 11000 | D10: -680000
A11: (Gains) losses on crypto | B11: 0 | C11: =-687000-71000 -> -758000 | D11: 550000
A12: Other | B12: =151000+298000-460000+96000-117000-117000 -> -149000 | C12: 11000 | D12: 62000
A13: Changes in working capital | B13: =84000-115000+8000+28000+43000 -> 48000 | C13: =-100000+47000+77000+48000-3000 -> 69000 | D13: =-2000+57000-148000-48000+108000 -> -33000
A14: Net Cash from Operating Activities | B14: =SUM(B6:B13) -> 675000 | C14: =SUM(C6:C13) -> 3104000 | D14: =SUM(D6:D13) -> 2426000

Sheet Analysis

Sheet Metrics
A2: Consolidated Statements of Operations (in $ thousands) | F2: Base | L2: Bear | P2: Bull
B3: Actual | F3: Forecast | L3: Forecast | P3: Forecast
A4: Line Item | B4: 2023A | C4: 2024A | D4: 2025A | F4: 2026 | G4: 2027 | H4: 2028 | I4: 2029 | J4: 2030 | L4: 2026 | M4: 2027 | N4: 2028 | P4: 2026 | Q4: 2027 | R4: 2028
A5: Transaction revenue:
A6: Txn revenue - consumer | B6: 1334000 | C6: 3430000 | D6: 3320000 | F6: =F49*F48 -> 3387825 | G6: =G49*G48 -> 3425467.5 | H6: =H49*H48 -> 3596740.9 | I6: =I49*I48 -> 3631324.9 | J6: =J49*J48 -> 3812891.2 | L6: =L49*L48 -> 2896680 | M6: =M49*M48 -> 2925646.8 | N6: =N49*N48 -> 2954903.3 | P6: =P49*P48 -> 3580220 | Q6: =Q49*Q48 -> 3830835.4 | R6: =R49*R48 -> 4098993.9
A7: Txn revenue - institutional | B7: 90000 | C7: 346000 | D7: 480000 | F7: =F51*F50 -> 513600 | G7: =G51*G50 -> 618360.49 | H7: =H51*H50 -> 721795.34 | I7: =I51*I50 -> 836681.09 | J7: =J51*J50 -> 895248.77 | L7: =L51*L50 -> 412440 | M7: =M51*M50 -> 433062 | N7: =N51*N50 -> 454715.1 | P7: =P51*P50 -> 648120 | Q7: =Q51*Q50 -> 772343 | R7: =R51*R50 -> 914929.4
A8: Txn revenue - other | B8: 96000 | C8: 210000 | D8: 253000 | F8: =D8 -> 253000 | G8: =F8 -> 253000 | H8: =G8 -> 253000 | I8: =H8 -> 253000 | J8: =I8 -> 253000 | L8: =D8 -> 253000 | M8: =L8 -> 253000 | N8: =M8 -> 253000 | P8: =D8 -> 253000 | Q8: =P8 -> 253000 | R8: =Q8 -> 253000
A9: Total transaction revenue | B9: =SUM(B6:B8) -> 1520000 | C9: =SUM(C6:C8) -> 3986000 | D9: =SUM(D6:D8) -> 4053000 | F9: =SUM(F6:F8) -> 4154425 | G9: =SUM(G6:G8) -> 4296828 | H9: =SUM(H6:H8) -> 4571536.2 | I9: =SUM(I6:I8) -> 4721006 | J9: =SUM(J6:J8) -> 4961139.9 | L9: =SUM(L6:L8) -> 3562120 | M9: =SUM(M6:M8) -> 3611708.8 | N9: =SUM(N6:N8) -> 3662618.4 | P9: =SUM(P6:P8) -> 4481340 | Q9: =SUM(Q6:Q8) -> 4856178.4 | R9: =SUM(R6:R8) -> 5266923.3
A11: Subscription and services revenue:
A12: Stablecoin revenue | B12: 694000 | C12: 910000 | D12: 1400000 | F12: =F54*F55 -> 1470000 | G12: =G54*G55 -> 1633640.4 | H12: =H54*H55 -> 1929737.7 | I12: =I54*I55 -> 2251360.7 | J12: =J54*J55 -> 2363928.7 | L12: =L54*L55 -> 1403041.5 | M12: =M54*M55 -> 1322600.5 | N12: =N54*N55 -> 1335826.5 | P12: =P54*P55 -> 1653088.5 | Q12: =Q54*Q55 -> 1939948 | R12: =R54*R55 -> 2251360.7
A13: Blockchain rewards revenue | B13: 331000 | C13: 706000 | D13: 723000 | F13: =D13*(1.04) -> 751920 | G13: =F13*(1.04) -> 781996.8 | H13: =G13*(1.04) -> 813276.67 | I13: =H13*(1.04) -> 845807.74 | J13: =I13*(1.04) -> 879640.05 | L13: =D13*(1.02) -> 737460 | M13: =L13*(1.02) -> 752209.2 | N13: =M13*(1.02) -> 767253.38 | P13: =D13*(1.06) -> 766380 | Q13: =P13*(1.06) -> 812362.8 | R13: =Q13*(1.06) -> 861104.57
A14: Interest and finance revenue | B14: 187000 | C14: 266000 | D14: 380000 | F14: =D14*(1.01) -> 383800 | G14: =F14*(1) -> 383800 | H14: =G14*(0.99) -> 379962 | I14: =H14*(0.99) -> 376162.38 | J14: =I14*(0.99) -> 372400.76 | L14: =D14*(0.97) -> 368600 | M14: =L14*(0.97) -> 357542 | N14: =M14*(0.97) -> 346815.74 | P14: =D14*(1.05) -> 399000 | Q14: =P14*(1.05) -> 418950 | R14: =Q14*(1.05) -> 439897.5
A15: Custodial and other | B15: 196000 | C15: 425000 | D15: 327000 | F15: =D15*(1.04) -> 340080 | G15: =F15*(1.04) -> 353683.2 | H15: =G15*(1.04) -> 367830.53 | I15: =H15*(1.04) -> 382543.75 | J15: =I15*(1.04) -> 397845.5 | L15: =D15*(1.02) -> 333540 | M15: =L15*(1.02) -> 340210.8 | N15: =M15*(1.02) -> 347015.02 | P15: =D15*(1.06) -> 346620 | Q15: =P15*(1.06) -> 367417.2 | R15: =Q15*(1.06) -> 389462.23
A16: Total subscription and services revenue | B16: =SUM(B12:B15) -> 1408000 | C16: =SUM(C12:C15) -> 2307000 | D16: =SUM(D12:D15) -> 2830000 | F16: =SUM(F12:F15) -> 2945800 | G16: =SUM(G12:G15) -> 3153120.4 | H16: =SUM(H12:H15) -> 3490806.9 | I16: =SUM(I12:I15) -> 3855874.5 | J16: =SUM(J12:J15) -> 4013815 | L16: =SUM(L12:L15) -> 2842641.5 | M16: =SUM(M12:M15) -> 2772562.5 | N16: =SUM(N12:N15) -> 2796910.6 | P16: =SUM(P12:P15) -> 3165088.5 | Q16: =SUM(Q12:Q15) -> 3538678 | R16: =SUM(R12:R15) -> 3941825
A18: Total other revenue | B18: =181000 -> 181000 | C18: 271000 | D18: 298000 | F18: =D18 -> 298000 | G18: =F18 -> 298000 | H18: =G18 -> 298000 | I18: =H18 -> 298000 | J18: =I18 -> 298000 | L18: =H18 -> 298000 | M18: =L18 -> 298000 | N18: =M18 -> 298000 | P18: =N18 -> 298000 | Q18: =P18 -> 298000 | R18: =Q18 -> 298000
A20: Total net revenue | B20: =B16+B9+B18 -> 3109000 | C20: =C16+C9+C18 -> 6564000 | D20: =D16+D9+D18 -> 7181000 | F20: =F16+F9+F18 -> 7398225 | G20: =G16+G9+G18 -> 7747948.4 | H20: =H16+H9+H18 -> 8360343.1 | I20: =I16+I9+I18 -> 8874880.6 | J20: =J16+J9+J18 -> 9272955 | L20: =L16+L9+L18 -> 6702761.5 | M20: =M16+M9+M18 -> 6682271.3 | N20: =N16+N9+N18 -> 6757529 | P20: =P16+P9+P18 -> 7944428.5 | Q20: =Q16+Q9+Q18 -> 8692856.4 | R20: =R16+R9+R18 -> 9506748.3
A23: Revenue Mix
A25: Txn revenue - consumer | B25: =B6/B$20 -> 0.42907687 | C25: =C6/C$20 -> 0.52254723 | D25: =D6/D$20 -> 0.46233115 | F25: =F6/F$20 -> 0.45792403 | G25: =G6/G$20 -> 0.44211284 | H25: =H6/H$20 -> 0.4302145 | I25: =I6/I$20 -> 0.40916888 | J25: =J6/J$20 -> 0.41118405 | L25: =L6/L$20 -> 0.43216218 | M25: =M6/M$20 -> 0.43782221 | N25: =N6/N$20 -> 0.43727571 | P25: =P6/P$20 -> 0.45065797 | Q25: =Q6/Q$20 -> 0.44068776 | R25: =R6/R$20 -> 0.43116676
A26: Txn revenue - institutional | B26: =B7/B$20 -> 0.028948215 | C26: =C7/C$20 -> 0.052711761 | D26: =D7/D$20 -> 0.066843058 | F26: =F7/F$20 -> 0.069422057 | G26: =G7/G$20 -> 0.079809578 | H26: =H7/H$20 -> 0.086335611 | I26: =I7/I$20 -> 0.094275195 | J26: =J7/J$20 -> 0.096544065 | L26: =L7/L$20 -> 0.061532847 | M26: =M7/M$20 -> 0.064807606 | N26: =N7/N$20 -> 0.067290144 | P26: =P7/P$20 -> 0.081581702 | Q26: =Q7/Q$20 -> 0.088848011 | R26: =R7/R$20 -> 0.096239995
A27: Txn revenue - other | B27: =B8/B$20 -> 0.030878096 | C27: =C8/C$20 -> 0.031992687 | D27: =D8/D$20 -> 0.035231862 | F27: =F8/F$20 -> 0.034197392 | G27: =G8/G$20 -> 0.032653806 | H27: =H8/H$20 -> 0.030261916 | I27: =I8/I$20 -> 0.028507426 | J27: =J8/J$20 -> 0.027283644 | L27: =L8/L$20 -> 0.037745637 | M27: =M8/M$20 -> 0.037861378 | N27: =N8/N$20 -> 0.037439721 | P27: =P8/P$20 -> 0.031846218 | Q27: =Q8/Q$20 -> 0.029104358 | R27: =R8/R$20 -> 0.026612675
A28: Total transaction revenue | B28: =B9/B$20 -> 0.48890318 | C28: =C9/C$20 -> 0.60725168 | D28: =D9/D$20 -> 0.56440607 | F28: =F9/F$20 -> 0.56154348 | G28: =G9/G$20 -> 0.55457623 | H28: =H9/H$20 -> 0.54681203 | I28: =I9/I$20 -> 0.5319515 | J28: =J9/J$20 -> 0.53501176 | L28: =L9/L$20 -> 0.53144066 | M28: =M9/M$20 -> 0.5404912 | N28: =N9/N$20 -> 0.54200557 | P28: =P9/P$20 -> 0.56408589 | Q28: =Q9/Q$20 -> 0.55864013 | R28: =R9/R$20 -> 0.55401943
A31: Stablecoin revenue | B31: =B12/B$20 -> 0.2232229 | C31: =C12/C$20 -> 0.13863498 | D31: =D12/D$20 -> 0.19495892 | F31: =F12/F$20 -> 0.19869631 | G31: =G12/G$20 -> 0.21084813 | H31: =H12/H$20 -> 0.2308204 | I31: =I12/I$20 -> 0.25367786 | J31: =J12/J$20 -> 0.25492723 | L31: =L12/L$20 -> 0.2093229 | M31: =M12/M$20 -> 0.19792678 | N31: =N12/N$20 -> 0.19767972 | P31: =P12/P$20 -> 0.20808149 | Q31: =Q12/Q$20 -> 0.22316577 | R31: =R12/R$20 -> 0.23681711
A32: Blockchain rewards revenue | B32: =B13/B$20 -> 0.1064651 | C32: =C13/C$20 -> 0.10755637 | D32: =D13/D$20 -> 0.10068236 | F32: =F13/F$20 -> 0.10163519 | G32: =G13/G$20 -> 0.10092953 | H32: =H13/H$20 -> 0.097277906 | I32: =I13/I$20 -> 0.095303563 | J32: =J13/J$20 -> 0.094860813 | L32: =L13/L$20 -> 0.11002331 | M32: =M13/M$20 -> 0.11256789 | N32: =N13/N$20 -> 0.11354052 | P32: =P13/P$20 -> 0.096467606 | Q32: =Q13/Q$20 -> 0.093451768 | R32: =R13/R$20 -> 0.090578245
A33: Interest and finance revenue | B33: =B14/B$20 -> 0.060147958 | C33: =C14/C$20 -> 0.040524071 | D33: =D14/D$20 -> 0.052917421 | F33: =F14/F$20 -> 0.051877308 | G33: =G14/G$20 -> 0.049535694 | H33: =H14/H$20 -> 0.045448135 | I33: =I14/I$20 -> 0.042385064 | J33: =J14/J$20 -> 0.04015988 | L33: =L14/L$20 -> 0.05499226 | M33: =M14/M$20 -> 0.053506059 | N33: =N14/N$20 -> 0.051322864 | P33: =P14/P$20 -> 0.050223877 | Q33: =Q14/Q$20 -> 0.048194745 | R33: =R14/R$20 -> 0.046272131
A34: Custodial and other | B34: =B15/B$20 -> 0.063042779 | C34: =C15/C$20 -> 0.064747105 | D34: =D15/D$20 -> 0.045536833 | F34: =F15/F$20 -> 0.045967783 | G34: =G15/G$20 -> 0.045648626 | H34: =H15/H$20 -> 0.043997061 | I34: =I15/I$20 -> 0.043104101 | J34: =J15/J$20 -> 0.042903853 | L34: =L15/L$20 -> 0.04976158 | M34: =M15/M$20 -> 0.05091245 | N34: =N15/N$20 -> 0.051352353 | P34: =P15/P$20 -> 0.043630577 | Q34: =Q15/Q$20 -> 0.042266567 | R34: =R15/R$20 -> 0.040966924
A35: Total subscription and services revenue | B35: =B16/B$20 -> 0.45287874 | C35: =C16/C$20 -> 0.35146252 | D35: =D16/D$20 -> 0.39409553 | F35: =F16/F$20 -> 0.39817659 | G35: =G16/G$20 -> 0.40696198 | H35: =H16/H$20 -> 0.4175435 | I35: =I16/I$20 -> 0.43447058 | J35: =J16/J$20 -> 0.43285178 | L35: =L16/L$20 -> 0.42410005 | M35: =M16/M$20 -> 0.41491319 | N35: =N16/N$20 -> 0.41389547 | P35: =P16/P$20 -> 0.39840355 | Q35: =Q16/Q$20 -> 0.40707885 | R35: =R16/R$20 -> 0.41463441
A37: Total other revenue | B37: =B18/B$20 -> 0.058218077 | C37: =C18/C$20 -> 0.041285801 | D37: =D18/D$20 -> 0.041498399 | F37: =F18/F$20 -> 0.040279932 | G37: =G18/G$20 -> 0.038461795 | H37: =H18/H$20 -> 0.03564447 | I37: =I18/I$20 -> 0.033577917 | J37: =J18/J$20 -> 0.032136466 | L37: =L18/L$20 -> 0.044459287 | M37: =M18/M$20 -> 0.044595616 | N37: =N18/N$20 -> 0.04409896 | P37: =P18/P$20 -> 0.037510565 | Q37: =Q18/Q$20 -> 0.034281022 | R37: =R18/R$20 -> 0.031346155
A40: Stablecoin revenue | B40: =B31/$B$35 -> 0.49289773 | C40: =C31/$C$35 -> 0.39445167 | D40: =D31/$D$35 -> 0.49469965 | F40: =F31/$B$35 -> 0.43874064 | G40: =G31/$C$35 -> 0.59991639 | H40: =H31/$D$35 -> 0.58569656 | I40: =I31/$D$35 -> 0.64369636 | J40: =J31/$D$35 -> 0.64686658 | L40: =L31/$B$35 -> 0.46220519 | M40: =M31/$C$35 -> 0.56315189 | N40: =N31/$D$35 -> 0.50160357 | P40: =P31/$B$35 -> 0.45946402 | Q40: =Q31/$C$35 -> 0.6349632 | R40: =R31/$D$35 -> 0.60091296
A41: Blockchain rewards revenue | B41: =B32/$B$35 -> 0.23508523 | C41: =C32/$C$35 -> 0.30602514 | D41: =D32/$D$35 -> 0.25547703 | F41: =F32/$B$35 -> 0.22442032 | G41: =G32/$C$35 -> 0.28717011 | H41: =H32/$D$35 -> 0.24683839 | I41: =I32/$D$35 -> 0.24182858 | J41: =J32/$D$35 -> 0.24070512 | L41: =L32/$B$35 -> 0.24294209 | M41: =M32/$C$35 -> 0.3202842 | N41: =N32/$D$35 -> 0.28810407 | P41: =P32/$B$35 -> 0.21300979 | Q41: =Q32/$C$35 -> 0.26589398 | R41: =R32/$D$35 -> 0.22983829
A42: Interest and finance revenue | B42: =B33/$B$35 -> 0.1328125 | C42: =C33/$C$35 -> 0.11530126 | D42: =D33/$D$35 -> 0.13427562 | F42: =F33/$B$35 -> 0.11455011 | G42: =G33/$C$35 -> 0.14094161 | H42: =H33/$D$35 -> 0.11532263 | I42: =I33/$D$35 -> 0.10755023 | J42: =J33/$D$35 -> 0.10190392 | L42: =L33/$B$35 -> 0.12142822 | M42: =M33/$C$35 -> 0.15223831 | N42: =N33/$D$35 -> 0.1302295 | P42: =P33/$B$35 -> 0.11089917 | Q42: =Q33/$C$35 -> 0.13712627 | R42: =R33/$D$35 -> 0.11741349
A43: Custodial and other | B43: =B34/$B$35 -> 0.13920455 | C43: =C34/$C$35 -> 0.18422193 | D43: =D34/$D$35 -> 0.1155477 | F43: =F34/$B$35 -> 0.1015013 | G43: =G34/$C$35 -> 0.12988192 | H43: =H34/$D$35 -> 0.1116406 | I43: =I34/$D$35 -> 0.10937475 | J43: =J34/$D$35 -> 0.10886663 | L43: =L34/$B$35 -> 0.10987837 | M43: =M34/$C$35 -> 0.14485883 | N43: =N34/$D$35 -> 0.13030433 | P43: =P34/$B$35 -> 0.096340529 | Q43: =Q34/$C$35 -> 0.1202591 | R43: =R34/$D$35 -> 0.10395176
A46: Trading Volume in $ thousands (as per 10-K) - this is Spot volume, as that is the main driver of the txn revenue
A48: Consumer | B48: 75000000 | C48: 224000000 | D48: 239000000 | F48: =D48*1.05 -> 250950000 | G48: =F48*1.05 -> 263497500 | H48: =G48*1.05 -> 276672375 | I48: =H48*1.05 -> 2.9050599e+08 | J48: =I48*1.05 -> 3.0503129e+08 | L48: =D48*1.01 -> 241390000 | M48: =L48*1.01 -> 243803900 | N48: =M48*1.01 -> 246241939 | P48: =D48*1.07 -> 255730000 | Q48: =P48*1.07 -> 273631100 | R48: =Q48*1.07 -> 292785277
A49: Take rate (%) | B49: =B6/B48 -> 0.017786667 | C49: =C6/C48 -> 0.0153125 | D49: =D6/D48 -> 0.013891213 | F49: 0.0135 | G49: 0.013 | H49: 0.013 | I49: 0.0125 | J49: 0.0125 | L49: 0.012 | M49: =L49 -> 0.012 | N49: =M49 -> 0.012 | P49: 0.014 | Q49: =P49 -> 0.014 | R49: =Q49 -> 0.014
A50: Institutional | B50: 393000000 | C50: 965000000 | D50: 982000000 | F50: =D50*(1.07) -> 1.05074e+09 | G50: =F50*(1.07) -> 1.1242918e+09 | H50: =G50*(1.07) -> 1.2029922e+09 | I50: =H50*(1.07) -> 1.2872017e+09 | J50: =I50*(1.07) -> 1.3773058e+09 | L50: =D50*(1.05) -> 1031100000 | M50: =L50*(1.05) -> 1082655000 | N50: =M50*(1.05) -> 1136787750 | P50: =D50*(1.1) -> 1080200000 | Q50: =P50*(1.1) -> 1188220000 | R50: =Q50*(1.1) -> 1307042000
A51: Take rate (%) | B51: =B7/B50 -> 0.00022900763 | C51: =C7/C50 -> 0.00035854922 | D51: =D7/D50 -> 0.00048879837 | F51: =D51 -> 0.00048879837 | G51: 0.00055 | H51: 0.0006 | I51: 0.00065 | J51: 0.00065 | L51: 0.0004 | M51: =L51 -> 0.0004 | N51: =M51 -> 0.0004 | P51: 0.0006 | Q51: 0.00065 | R51: 0.0007
A54: USDC - Assets on platform | B54: 2367276000 | C54: 6091000000 | D54: 9261000000 | F54: =D54*(1.05) -> 9724050000 | G54: =F54*1.05 -> 10210252500 | H54: =G54*1.05 -> 10720765125 | I54: =H54*1.05 -> 1.1256803e+10 | J54: =I54*1.05 -> 1.1819644e+10 | L54: =D54*(1.01) -> 9353610000 | M54: =L54*(1.01) -> 9447146100 | N54: =M54*(1.01) -> 9541617561 | P54: =D54*(1.05) -> 9724050000 | Q54: =P54*(1.05) -> 10210252500 | R54: =Q54*(1.05) -> 10720765125
A55: take rate | B55: =B12/B54 -> 0.00029316396 | C55: =C12/C54 -> 0.00014940076 | D55: =D12/D54 -> 0.00015117158 | F55: =D55 -> 0.00015117158 | G55: 0.00016 | H55: 0.00018 | I55: 0.0002 | J55: 0.0002 | L55: 0.00015 | M55: 0.00014 | N55: 0.00014 | P55: 0.00017 | Q55: 0.00019 | R55: 0.00021

Sheet Model
F1: Base | L1: Bear | P1: Bull
C2: Historicals | F2: Forecast | L2: Forecast | P2: Forecast
B3: $ in millions | C3: 2023 | D3: 2024 | E3: 2025 | F3: 2026 | G3: 2027 | H3: 2028 | I3: 2029 | J3: 2030 | L3: 2026 | M3: 2027 | N3: 2028 | P3: 2026 | Q3: 2027 | R3: 2028
B4: =IS!A6 -> Transaction revenue - consumer, net | C4: =IS!B6 -> 1334000 | D4: =IS!C6 -> 3430000 | E4: =IS!D6 -> 3320000 | F4: =Metrics!F6 -> 3387825 | G4: =Metrics!G6 -> 3425467.5 | H4: =Metrics!H6 -> 3596740.9 | I4: =Metrics!I6 -> 3631324.9 | J4: =Metrics!J6 -> 3812891.2 | L4: =Metrics!L6 -> 2896680 | M4: =Metrics!M6 -> 2925646.8 | N4: =Metrics!N6 -> 2954903.3 | P4: =Metrics!P6 -> 3580220 | Q4: =Metrics!Q6 -> 3830835.4 | R4: =Metrics!R6 -> 4098993.9
B5: =IS!A7 -> Transaction revenue - institutional, net | C5: =IS!B7 -> 90000 | D5: =IS!C7 -> 346000 | E5: =IS!D7 -> 480000 | F5: =Metrics!F7 -> 513600 | G5: =Metrics!G7 -> 618360.49 | H5: =Metrics!H7 -> 721795.34 | I5: =Metrics!I7 -> 836681.09 | J5: =Metrics!J7 -> 895248.77 | L5: =Metrics!L7 -> 412440 | M5: =Metrics!M7 -> 433062 | N5: =Metrics!N7 -> 454715.1 | P5: =Metrics!P7 -> 648120 | Q5: =Metrics!Q7 -> 772343 | R5: =Metrics!R7 -> 914929.4
B6: =IS!A8 -> Transaction revenue - other, net | C6: =IS!B8 -> 96000 | D6: =IS!C8 -> 210000 | E6: =IS!D8 -> 253000 | F6: =Metrics!F8 -> 253000 | G6: =Metrics!G8 -> 253000 | H6: =Metrics!H8 -> 253000 | I6: =Metrics!I8 -> 253000 | J6: =Metrics!J8 -> 253000 | L6: =Metrics!L8 -> 253000 | M6: =Metrics!M8 -> 253000 | N6: =Metrics!N8 -> 253000 | P6: =Metrics!P8 -> 253000 | Q6: =Metrics!Q8 -> 253000 | R6: =Metrics!R8 -> 253000
B7: =IS!A12 -> Stablecoin revenue | C7: =IS!B12 -> 694000 | D7: =IS!C12 -> 910000 | E7: =IS!D12 -> 1400000 | F7: =Metrics!F12 -> 1470000 | G7: =Metrics!G12 -> 1633640.4 | H7: =Metrics!H12 -> 1929737.7 | I7: =Metrics!I12 -> 2251360.7 | J7: =Metrics!J12 -> 2363928.7 | L7: =Metrics!L12 -> 1403041.5 | M7: =Metrics!M12 -> 1322600.5 | N7: =Metrics!N12 -> 1335826.5 | P7: =Metrics!P12 -> 1653088.5 | Q7: =Metrics!Q12 -> 1939948 | R7: =Metrics!R12 -> 2251360.7
B8: =IS!A13 -> Blockchain rewards revenue | C8: =IS!B13 -> 331000 | D8: =IS!C13 -> 706000 | E8: =IS!D13 -> 723000 | F8: =Metrics!F13 -> 751920 | G8: =Metrics!G13 -> 781996.8 | H8: =Metrics!H13 -> 813276.67 | I8: =Metrics!I13 -> 845807.74 | J8: =Metrics!J13 -> 879640.05 | L8: =Metrics!L13 -> 737460 | M8: =Metrics!M13 -> 752209.2 | N8: =Metrics!N13 -> 767253.38 | P8: =Metrics!P13 -> 766380 | Q8: =Metrics!Q13 -> 812362.8 | R8: =Metrics!R13 -> 861104.57
B9: =IS!A14 -> Interest and finance revenue | C9: =IS!B14 -> 187000 | D9: =IS!C14 -> 266000 | E9: =IS!D14 -> 380000 | F9: =Metrics!F14 -> 383800 | G9: =Metrics!G14 -> 383800 | H9: =Metrics!H14 -> 379962 | I9: =Metrics!I14 -> 376162.38 | J9: =Metrics!J14 -> 372400.76 | L9: =Metrics!L14 -> 368600 | M9: =Metrics!M14 -> 357542 | N9: =Metrics!N14 -> 346815.74 | P9: =Metrics!P14 -> 399000 | Q9: =Metrics!Q14 -> 418950 | R9: =Metrics!R14 -> 439897.5
B10: =IS!A15 -> Custodial and other | C10: =IS!B15 -> 196000 | D10: =IS!C15 -> 425000 | E10: =IS!D15 -> 327000 | F10: =Metrics!F15 -> 340080 | G10: =Metrics!G15 -> 353683.2 | H10: =Metrics!H15 -> 367830.53 | I10: =Metrics!I15 -> 382543.75 | J10: =Metrics!J15 -> 397845.5 | L10: =Metrics!L15 -> 333540 | M10: =Metrics!M15 -> 340210.8 | N10: =Metrics!N15 -> 347015.02 | P10: =Metrics!P15 -> 346620 | Q10: =Metrics!Q15 -> 367417.2 | R10: =Metrics!R15 -> 389462.23
B11: =IS!A18 -> Total other revenue | C11: =IS!B18 -> 181000 | D11: =IS!C18 -> 271000 | E11: =IS!D18 -> 298000 | F11: =Metrics!F18 -> 298000 | G11: =Metrics!G18 -> 298000 | H11: =Metrics!H18 -> 298000 | I11: =Metrics!I18 -> 298000 | J11: =Metrics!J18 -> 298000 | L11: =Metrics!L18 -> 298000 | M11: =Metrics!M18 -> 298000 | N11: =Metrics!N18 -> 298000 | P11: =Metrics!P18 -> 298000 | Q11: =Metrics!Q18 -> 298000 | R11: =Metrics!R18 -> 298000
B12: Total Revenue | C12: =SUM(C4:C11) -> 3109000 | D12: =SUM(D4:D11) -> 6564000 | E12: =SUM(E4:E11) -> 7181000 | F12: =SUM(F4:F11) -> 7398225 | G12: =SUM(G4:G11) -> 7747948.4 | H12: =SUM(H4:H11) -> 8360343.1 | I12: =SUM(I4:I11) -> 8874880.6 | J12: =SUM(J4:J11) -> 9272955 | L12: =SUM(L4:L11) -> 6702761.5 | M12: =SUM(M4:M11) -> 6682271.3 | N12: =SUM(N4:N11) -> 6757529 | P12: =SUM(P4:P11) -> 7944428.5 | Q12: =SUM(Q4:Q11) -> 8692856.4 | R12: =SUM(R4:R11) -> 9506748.3
B13: % Growth | D13: =(D12-C12)/C12 -> 1.1112898 | E13: =(E12-D12)/D12 -> 0.093997562 | F13: =(F12-E12)/E12 -> 0.030249965 | G13: =(G12-F12)/F12 -> 0.047271256 | H13: =(H12-G12)/G12 -> 0.0790396 | I13: =(I12-H12)/H12 -> 0.061545013 | J13: =(J12-I12)/I12 -> 0.044854056 | L13: =(L12-E12)/E12 -> -0.066597758 | M13: =(M12-L12)/L12 -> -0.0030569857 | N13: =(N12-M12)/M12 -> 0.011262295 | P13: =(P12-E12)/E12 -> 0.10631228 | Q13: =(Q12-P12)/P12 -> 0.094207894 | R13: =(R12-Q12)/Q12 -> 0.093627669
B15: Segment Growth %
B16: Transaction revenue - consumer, net | D16: =(D4-C4)/C4 -> 1.5712144 | E16: =(E4-D4)/D4 -> -0.032069971 | F16: =(F4-E4)/E4 -> 0.020429217 | G16: =(G4-F4)/F4 -> 0.011111111 | H16: =(H4-G4)/G4 -> 0.05 | I16: =(I4-H4)/H4 -> 0.0096153846 | J16: =(J4-I4)/I4 -> 0.05 | L16: =(L4-E4)/E4 -> -0.12750602 | M16: =(M4-L4)/L4 -> 0.01 | N16: =(N4-M4)/M4 -> 0.01 | P16: =(P4-E4)/E4 -> 0.078379518 | Q16: =(Q4-P4)/P4 -> 0.07 | R16: =(R4-Q4)/Q4 -> 0.07
B17: Transaction revenue - institutional, net | D17: =(D5-C5)/C5 -> 2.8444444 | E17: =(E5-D5)/D5 -> 0.38728324 | F17: =(F5-E5)/E5 -> 0.07 | G17: =(G5-F5)/F5 -> 0.20397292 | H17: =(H5-G5)/G5 -> 0.16727273 | I17: =(I5-H5)/H5 -> 0.15916667 | J17: =(J5-I5)/I5 -> 0.07 | L17: =(L5-E5)/E5 -> -0.14075 | M17: =(M5-L5)/L5 -> 0.05 | N17: =(N5-M5)/M5 -> 0.05 | P17: =(P5-E5)/E5 -> 0.35025 | Q17: =(Q5-P5)/P5 -> 0.19166667 | R17: =(R5-Q5)/Q5 -> 0.18461538
B18: Transaction revenue - other, net | D18: =(D6-C6)/C6 -> 1.1875 | E18: =(E6-D6)/D6 -> 0.2047619 | F18: =(F6-E6)/E6 -> 0 | G18: =(G6-F6)/F6 -> 0 | H18: =(H6-G6)/G6 -> 0 | I18: =(I6-H6)/H6 -> 0 | J18: =(J6-I6)/I6 -> 0 | L18: =(L6-E6)/E6 -> 0 | M18: =(M6-L6)/L6 -> 0 | N18: =(N6-M6)/M6 -> 0 | P18: =(P6-E6)/E6 -> 0 | Q18: =(Q6-P6)/P6 -> 0 | R18: =(R6-Q6)/Q6 -> 0
B19: Stablecoin revenue | D19: =(D7-C7)/C7 -> 0.31123919 | E19: =(E7-D7)/D7 -> 0.53846154 | F19: =(F7-E7)/E7 -> 0.05 | G19: =(G7-F7)/F7 -> 0.11132 | H19: =(H7-G7)/G7 -> 0.18125 | I19: =(I7-H7)/H7 -> 0.16666667 | J19: =(J7-I7)/I7 -> 0.05 | L19: =(L7-E7)/E7 -> 0.0021725 | M19: =(M7-L7)/L7 -> -0.057333333 | N19: =(N7-M7)/M7 -> 0.01 | P19: =(P7-E7)/E7 -> 0.1807775 | Q19: =(Q7-P7)/P7 -> 0.17352941 | R19: =(R7-Q7)/Q7 -> 0.16052632
B20: Blockchain rewards revenue | D20: =(D8-C8)/C8 -> 1.1329305 | E20: =(E8-D8)/D8 -> 0.02407932 | F20: =(F8-E8)/E8 -> 0.04 | G20: =(G8-F8)/F8 -> 0.04 | H20: =(H8-G8)/G8 -> 0.04 | I20: =(I8-H8)/H8 -> 0.04 | J20: =(J8-I8)/I8 -> 0.04 | L20: =(L8-E8)/E8 -> 0.02 | M20: =(M8-L8)/L8 -> 0.02 | N20: =(N8-M8)/M8 -> 0.02 | P20: =(P8-E8)/E8 -> 0.06 | Q20: =(Q8-P8)/P8 -> 0.06 | R20: =(R8-Q8)/Q8 -> 0.06
B21: Interest and finance revenue | D21: =(D9-C9)/C9 -> 0.42245989 | E21: =(E9-D9)/D9 -> 0.42857143 | F21: =(F9-E9)/E9 -> 0.01 | G21: =(G9-F9)/F9 -> 0 | H21: =(H9-G9)/G9 -> -0.01 | I21: =(I9-H9)/H9 -> -0.01 | J21: =(J9-I9)/I9 -> -0.01 | L21: =(L9-E9)/E9 -> -0.03 | M21: =(M9-L9)/L9 -> -0.03 | N21: =(N9-M9)/M9 -> -0.03 | P21: =(P9-E9)/E9 -> 0.05 | Q21: =(Q9-P9)/P9 -> 0.05 | R21: =(R9-Q9)/Q9 -> 0.05
B22: Custodial and other | D22: =(D10-C10)/C10 -> 1.1683673 | E22: =(E10-D10)/D10 -> -0.23058824 | F22: =(F10-E10)/E10 -> 0.04 | G22: =(G10-F10)/F10 -> 0.04 | H22: =(H10-G10)/G10 -> 0.04 | I22: =(I10-H10)/H10 -> 0.04 | J22: =(J10-I10)/I10 -> 0.04 | L22: =(L10-E10)/E10 -> 0.02 | M22: =(M10-L10)/L10 -> 0.02 | N22: =(N10-M10)/M10 -> 0.02 | P22: =(P10-E10)/E10 -> 0.06 | Q22: =(Q10-P10)/P10 -> 0.06 | R22: =(R10-Q10)/Q10 -> 0.06
B23: Total other revenue | D23: =(D11-C11)/C11 -> 0.49723757 | E23: =(E11-D11)/D11 -> 0.099630996 | F23: =(F11-E11)/E11 -> 0 | G23: =(G11-F11)/F11 -> 0 | H23: =(H11-G11)/G11 -> 0 | I23: =(I11-H11)/H11 -> 0 | J23: =(J11-I11)/I11 -> 0 | L23: =(L11-E11)/E11 -> 0 | M23: =(M11-L11)/L11 -> 0 | N23: =(N11-M11)/M11 -> 0 | P23: =(P11-E11)/E11 -> 0 | Q23: =(Q11-P11)/P11 -> 0 | R23: =(R11-Q11)/Q11 -> 0
B26: (-) COGS | C26: =-(IS!B23+IS!B24) -> -1746000 | D26: =-(IS!C23+IS!C24) -> -2366000 | E26: =-(IS!D23+IS!D24) -> -2730000 | F26: =F27-F12 -> -2885307.8 | G26: =G27-G12 -> -2944220.4 | H26: =H27-H12 -> -3093327 | I26: =I27-I12 -> -3194957 | J26: =J27-J12 -> -3430993.3 | L26: =L27-L12 -> -2614077 | M26: =M27-M12 -> -2539263.1 | N26: =N27-N12 -> -2500285.7 | P26: =P27-P12 -> -3098327.1 | Q26: =Q27-Q12 -> -3303285.4 | R26: =R27-R12 -> -3517496.9
B27: Gross Profit | C27: =C12+C26 -> 1363000 | D27: =D12+D26 -> 4198000 | E27: =E12+E26 -> 4451000 | F27: =F12*F28 -> 4512917.2 | G27: =G12*G28 -> 4803728 | H27: =H12*H28 -> 5267016.2 | I27: =I12*I28 -> 5679923.6 | J27: =J12*J28 -> 5841961.6 | L27: =L12*L28 -> 4088684.5 | M27: =M12*M28 -> 4143008.2 | N27: =N12*N28 -> 4257243.2 | P27: =P12*P28 -> 4846101.4 | Q27: =Q12*Q28 -> 5389571 | R27: =R12*R28 -> 5989251.4
B28: Gross Margin % | C28: =C27/C12 -> 0.43840463 | D28: =D27/D12 -> 0.63954906 | E28: =E27/E12 -> 0.61983011 | F28: 0.61 | G28: 0.62 | H28: 0.63 | I28: 0.64 | J28: 0.63 | L28: =F28 -> 0.61 | M28: =G28 -> 0.62 | N28: =H28 -> 0.63 | P28: =L28 -> 0.61 | Q28: =M28 -> 0.62 | R28: =N28 -> 0.63
B30: (-) Opex | C30: =-SUM(IS!B25:B30) -> -1523000 | D30: =-SUM(IS!C25:C30) -> -1890000 | E30: =-SUM(IS!D25:D30) -> -3015000 | F30: =F31-F27 -> -2663361 | G30: =G31-G27 -> -2789261.4 | H30: =H31-H27 -> -2926120.1 | I30: =I31-I27 -> -3194957 | J30: =J31-J27 -> -3245534.2 | L30: =L31-L27 -> -2412994.1 | M30: =M31-M27 -> -2405617.7 | N30: =N31-N27 -> -2365135.1 | P30: =P31-P27 -> -2859994.3 | Q30: =Q31-Q27 -> -3129428.3 | R30: =R31-R27 -> -3327361.9
B31: EBITDA | C31: =C27+C30 -> -160000 | D31: =D27+D30 -> 2308000 | E31: =E27+E30 -> 1436000 | F31: =F32*F12 -> 1849556.2 | G31: =G32*G12 -> 2014466.6 | H31: =H32*H12 -> 2340896.1 | I31: =I32*I12 -> 2484966.6 | J31: =J32*J12 -> 2596427.4 | L31: =L32*L12 -> 1675690.4 | M31: =M32*M12 -> 1737390.5 | N31: =N32*N12 -> 1892108.1 | P31: =P32*P12 -> 1986107.1 | Q31: =Q32*Q12 -> 2260142.7 | R31: =R32*R12 -> 2661889.5
B32: EBITDA Margin | C32: =C31/C12 -> -0.051463493 | D32: =D31/D12 -> 0.35161487 | E32: =E31/E12 -> 0.19997215 | F32: 0.25 | G32: 0.26 | H32: 0.28 | I32: 0.28 | J32: 0.28 | L32: =F32 -> 0.25 | M32: =G32 -> 0.26 | N32: =H32 -> 0.28 | P32: =L32 -> 0.25 | Q32: =M32 -> 0.26 | R32: =N32 -> 0.28

Sheet DCF
C1: 2025 | D1: 2026 | E1: 2027 | F1: 2028 | G1: 2029 | H1: 2030 | J1: Beta | K1: =0.4*2.659+0.3*0.68+0.3*0.912 -> 1.5412 | L1: https://pages.stern.nyu.edu/~adamodar/New_Home_Page/datafile/totalbeta.html | M1: used Beta computed via Python script + website
B2: EBIT | C2: =Model!E31 -> 1436000 | D2: =Model!F31 -> 1849556.2 | E2: =Model!G31 -> 2014466.6 | F2: =Model!H31 -> 2340896.1 | G2: =Model!I31 -> 2484966.6 | H2: =Model!J31 -> 2596427.4 | J2: Risk Free | K2: 0.0427 | L2: 10 Year US
B3: +D&A | C3: =CF!D7 -> 189000 | D3: =C3*(1.05) -> 198450 | E3: =D3*(1.05) -> 208372.5 | F3: =E3*(1.05) -> 218791.12 | G3: =F3*(1.05) -> 229730.68 | H3: =G3*(1.05) -> 241217.22 | J3: ERP | K3: 0.0446 | L3: https://pages.stern.nyu.edu/~adamodar/New_Home_Page/datafile/ctryprem.html
B4: -Tax | C4: =-IS!D38 -> -262000 | D4: =-D2*IS!$D$41 -> -337453.86 | E4: =-E2*IS!$D$41 -> -367541.95 | F4: =-F2*IS!$D$41 -> -427099.42 | G4: =-G2*IS!$D$41 -> -453385.26 | H4: =-H2*IS!$D$41 -> -473721.43 | J4: Market Cap | K4: 51000000
B5: -CAPEX | C5: -110595 | D5: =C5*(1.02) -> -112806.9 | E5: =D5*(1.02) -> -115063.04 | F5: =E5*(1.02) -> -117364.3 | G5: =F5*(1.02) -> -119711.58 | H5: =G5*(1.02) -> -122105.82 | J5: Debt | K5: =BS!C44+BS!C37+BS!C38 -> 7660000
B6: -Change in working capital | C6: =CF!D13 -> -33000 | D6: =AVERAGE(CF!B13:D13) -> 28000 | E6: =D6 -> 28000 | F6: =E6 -> 28000 | G6: =F6 -> 28000 | H6: =G6 -> 28000 | J6: Cost of equity | K6: =K2+K3*K1 -> 0.11143752
J7: Cost of debt | K7: =K2+2.4% -> 0.0667
B8: FCF | C8: =C2+C3+C4+C5-C6 -> 1285405 | D8: =D2+D3+D4+D5-D6 -> 1569745.5 | E8: =E2+E3+E4+E5-E6 -> 1712234.1 | F8: =F2+F3+F4+F5-F6 -> 1987223.5 | G8: =G2+G3+G4+G5-G6 -> 2113600.4 | H8: =H2+H3+H4+H5-H6 -> 2213817.4 | J8: growth | K8: 0.03
B9: TV | H9: =((H8*(1+K8))/(K10-K8)) -> 30163569
B10: Discount rate | D10: =(1+$K$10)^1 -> 1.1055956 | E10: =(1+$K$10)^2 -> 1.2223415 | F10: =(1+$K$10)^3 -> 1.3514154 | G10: =(1+$K$10)^4 -> 1.4941188 | H10: =(1+$K$10)^5 -> 1.6518912 | J10: Cost of capital | K10: =((K4/(K5+K4))*K6)+((K5/(K5+K4))*K7) -> 0.10559556
B12: Discounted FCF | C12: =C8 -> 1285405 | D12: =D8/D10 -> 1419818.9 | E12: =E8/E10 -> 1400782.1 | F12: =F8/F10 -> 1470475.7 | G12: =G8/G10 -> 1414613.3 | H12: =H8/H10 -> 1340171.4
B13: Discounted TV | H13: =H9/H10 -> 18260022
B19: EV | C19: =SUM(C12:H13) -> 26591288
B20: Cash | C20: =BS!C8+BS!C16+BS!C22+BS!C21 -> 14220000
B21: Debt | C21: =-K5 -> -7660000
B22: Equity Value | C22: =SUM(C19:C21) -> 33151288

Sheet Comps
A2: Ticker | B2: Market Cap | C2: EV | D2: EV/REV | E2: EV/EBITDA | F2: EV/GM | G2: Trailing PE | H2: Earnings Growth | I2: Rev Growth
A3: COIN | B3: 52.726149 | C3: 47.897391 | D3: 6.958 | E3: 28.661 | F3: 8.1691902 | G3: 43.840805 | H3: NaN | I3: -0.222
A4: CME | B4: 111.95217 | C4: 110.89127 | D4: 17.042 | E4: 24.159 | F4: 17.042366 | G4: 27.928251 | H4: 0.35 | I4: 0.08
A5: NDAQ | B5: 48.837239 | C5: 57.536004 | D5: 10.961 | E5: 18.459 | F5: 10.961327 | G5: 27.679611 | H5: 0.476 | I5: 0.134
A6: HOOD | B6: 66.073633 | C6: 65.887633 | D6: 14.73 | E6: 30.85 | F6: 15.945784 | G6: 35.8 | H6: -0.345 | I6: 0.265
A7: IBKR | B7: 112.52389 | C7: 108.34 | D7: 10.6 | E7: 11.922527 | F7: 11.83 | G7: 29.815315 | H7: 0.303 | I7: 0.152
A9: Average (exchanges) | D9: =AVERAGE(D4:D5) -> 14.0015 | E9: =AVERAGE(E4:E7) -> 21.347632 | F9: =AVERAGE(F4:F7) -> 13.944869 | G9: =AVERAGE(G4:G7) -> 30.305794
A10: Average (brokers) | D10: =AVERAGE(D6:D7) -> 12.665 | E10: =MEDIAN(E4:E7) -> 21.309 | F10: =MEDIAN(F4:F7) -> 13.887892 | G10: =MEDIAN(G4:G7) -> 28.871783
A13: Ticker | B13: Market Cap | C13: EV | D13: EV/REV | E13: EV/EBITDA | F13: EV/GM | G13: Trailing PE | H13: Earnings Growth | I13: Rev Growth
A14: MA | B14: 444.42504 | C14: 453.05761 | D14: 13.817 | E14: 22.053 | F14: 13.816524 | G14: 30.126434 | H14: 0.242 | I14: 0.176
A15: V | B15: 592.17812 | C15: 590.82192 | D15: 14.274 | E15: 20.382 | F15: 14.598692 | G15: 28.812384 | H15: 0.174 | I15: 0.146
A16: PYPL | B16: 42.010776 | C16: 43.211837 | D16: 1.303 | E16: 6.499 | F16: 3.14015 | G16: 8.299446 | H16: 0.394 | I16: 0.037
A17: CRCL | B17: 30.631152 | C17: 26.463107 | D17: 9.635 | E17: -304.913 | F17: 111.13985 | G17: NaN | H17: 8.802 | I17: 0.769
A20: Average | D20: =AVERAGE(D14:D16) -> 9.798 | E20: =AVERAGE(E14:E16) -> 16.311333 | F20: =AVERAGE(F14:F16) -> 10.518455 | G20: =AVERAGE(G14:G16) -> 22.412755
A25: Revenue | B25: =Model!E12 -> 7181000
A26: Multiple | B26: =D9*0.25+D20*0.25+0.5*D10 -> 12.282375
A27: EV | B27: =B25*B26 -> 88199735
A28: Discount | B28: -0.25 | C28: Discount is due to the nature of cyclical business - feels correct to reduce it since all other companies have stable revenues and moats
A29: Final eV | B29: =B27*(1+B28) -> 66149801
